# 프로미스 개념부터 활용까지

## Promise 

자바스크립트에서  `콜백함수 대신` 비동기처리를 간편하게 처리할 수 잇도록 제공하는 객체이다 (약속)

정해진 기능을 수행했다면, 성공의 메시지와 함께 결과값을 반환하고, 
처리하지 못했을 때에는 error를 반환한다

> 예시

아직 강의 개설하지는 않았지만, pre-enrollment 하게 되면 Promise를 생성하는 시스템이다.
수업이 이미 오픈된 상태에서 사전공지창에서 pre-enrollment 버튼을 누른다 하더라도 이미 성공적으로 처리된 Promise 이기 때문에 바로 수강신청이 가능하다


> point

- state : 진행중인지, 성공했는지, 실패했는지
- 정보를 제공하는 producer, 정보를 소비하는 consumer

State : pending => fulfilled or rejected
Producer vs Consumer

## 1. Producer

```javascript
// 클래스이기 때문에 new 키워드를 통해 객체를 생성한다
// resolve, reject 두 가지의 콜백함수를 인자로 가진다
const promise = new Promise(resolve, reject) => {
  // doing some heavy work (network, read files)
  console.log('doing something...');

  // 서버 통신하는 것처럼 setTimeout
  setTimeout(() => resolve('ellie'), 2000);
}
```

Promise를 만드는 순간 전달한 resolve, reject 콜백함수가 바로 실행된다.
만약 사용자가 요구했을 때만 네트워크 요청을 하는 경우, 이렇게 코드를 작성하면 사용자가 요청하지도 않았는데 네트워크 요청이 될 것이기 때문에 주의해야 한다

지금은 비록 ~~setTimeout() 함수를 사용하긴 했지만,~~ 서버통신을 했을 때 성공적으로 받아온 응답값 및 응답값을 가공한 데이터를 resolve함수에 전달해주면 된다.

## 2. Consumer
   
### resolve 호출

Promise에서 값을 잘 가져온다면 then의 콜백함수를 실행한다

```javascript 
const promise = new Promise(resolve, reject) => {
  console.log('doing something...');
  setTimeout(() => resolve('ellie'), 2000);
}

promise.then(value => {
  console.log(value);
})
```

### reject 호출

만약 네트워크를 하다 실패한다면 error 객체를 통해 전달한다

error 클래스는 자바스크립트에서 제공하는 오브젝트 중 하나이다.
에러 오브젝트 시간에 더 다루기로 하고, 보통은 에러가 발생한 이유에 대해 적는다

이렇게 발생한 error의 내용을 catch 메서드의 콜백함수를 통해 확인할 수 있다.

```javascript 
const promise = new Promise(resolve, reject) => {
  console.log('doing something...');
  setTimeout(() => reject(new Error('no network')), 2000);
}

promise
  .then(value => {
    console.log(value);
})
  .catch(error => {
    console.log(error);
  })
  .finally(()=> console.log('finally'));
```

위와 같이 then을 호출하게 되면 다시 promise가 리턴되고
리턴된 promise에 catch를 등록하게 된다.

promise 오브젝트 내부에는 비동기적으로 처리하고 싶은 코드를 입력하고,
성공적으로 처리되었다면 resolve를 호출하고, 
실패했다면 실패한 이유와 함께 reject 함수를 호출한다.

finally는 성공하던 실패하던 모두 `마지막으로` 호출하는 함수이다.

### 3. Promise Chaining

then은 바로 값을 전달할 수도 있고 아니면 비동기인 promise를 전달할 수도 있다

```javascript
const fetNumber = new Primise(resolve, reject) => {
  setTimeout(() => resolve(1), 1000);
});

fetNumber
.then(num => num * 2) // num = 1
.then(num => num * 3) // num = 2
.then(num => { // num = 6
  return new Promise(resolve, reject) => {
  setTimeout(()=>resolve(num-1), 1000);  // resolve 매개변수 5
  }
});
.then(num => console.log(num)); // 5
// 총 2초의 시간이 걸린다 
```

### 4. 오류처리

> 정상적으로 처리되었을 때의 코드

```javascript
const getHen = () => {
  new Promise((resolve, reject) => {
    setTimeout(() => resolve('hen'), 1000);
  });
};

const getEgg = hen => {
  new Promise((resolve, reject) => {
    setTimeout(() => resolve(`${hen} => egg`), 1000);
  });
};

const cook = egg => {
  new Promise((resolve, reject) => {
    setTimeout(() => resolve(`${egg} => fried egg`), 1000);
  });
}

getHen()
.then(hen => getEgg(hen))
.then(egg => cook(egg))
.then(meal => console.log(meal));

// 실행결과 : hen => egg => fried egg
```

> #### 💡 받아온 하나의 value를 콜백함수에서 매개변수로 바로 사용할 때 생략이 가능하다

```javascript
getHen() // prettier 에서 한줄로 되기 때문에 주석표시를 해주면 여러줄이 된다
.then(getEgg)
.then(cook)
.then(console.log);
```

> 만약 여기서 getEgg 함수에서 에러가 발생했다면

```javascript
const getHen = () => {
  new Promise((resolve, reject) => {
    setTimeout(() => resolve('hen'), 1000);
  });
};

const getEgg = hen => {
  new Promise((resolve, reject) => {
    setTimeout(() => reject(new Error(`error! ${hen} => egg`)), 1000);
  });
};

const cook = egg => {
  new Promise((resolve, reject) => {
    setTimeout(() => resolve(`${egg} => fried egg`), 1000);
  });
}

getHen()
.then(getEgg)
.then(cook)
.then(console.log);
```

여기서 어떠한 error handling을 하지 않았기 때문에 콘솔에 `Uncaught (in promise) Error: error! hen => egg at 위치`
이렇게 발생하는데 이 때 catch로 처리를 해주게 되면 해당 로직이 실행된다

```javascript
getHen()
.then(getEgg)
.then(cook)
.then(console.log);
.catch(console.log); // 이번같은 경우는 console.log
```

이처럼 에러가 제일 밑으로 전달되면서 catch가 잡힌다

> 오류처리 : 달걀을 받아올 때 문제가 발생했을 때 다른 재료로 대체하고 싶은 경우,

```javascript
getHen()
.then(getEgg)
.catch(error => {  // 여기!
  return 'bread'
})
.then(cook)
.then(console.log);
.catch(console.log);

// 실행결과 : bread => fried edd
```

전달받은 error를 bread로 대체해서 전체적인 promise chaining에 문제가 발생하지 않도록 처리할 수 있다.

`해당하는 곳` 에서 발생하는 에러를 처리하고 싶은 경우, 그 다음줄에 바로 catch를 처리하면 된다

### 5. callback 지옥 -> promise 변환

#### 콜백지옥

```javascript
class UserStorage {
  loginUser(id, password, onSucess, onError) {
    setTimeout(()=>{
      if (
        (id === 'ellie' && password === 'dream') ||
        (id === 'coder' && password === 'academy')
      ) {
        onSucess(id);
      } else {
        onError(new Error('not found'));
      }
    }, 2000)
  }

  getRoles(user, onSuccess, onError) {
    setTimeout(()=> {
      if (user === 'ellie') {
        onSuccess({ name: 'ellie', role: 'admin' });
      } else {
        onError(new Error('no access'));
      }
    }, 1000);
  }
}

const userStorage = new UserStorage();
const id = prompt('enter your id');
const password = promt('enter ypur password');
userStorage.loginUser
(id, 
password, 
user => {
  userStorage.getGRole(
    user, 
    userWithRole => {
      alert(`Hello ${userWithRole.name}, you have a ${userWithRole.role} role.`)
    },
    error => { console.log(error) })
},
error => {
  console.log(error)
  }
);
```

#### Promise 변환

```javascript
class UserStorage {
  loginUser(id, password) {
    return new Promise(resolve, reject) => {
      setTimeout(()=>{
        if (
          (id === 'ellie' && password === 'dream') ||
          (id === 'coder' && password === 'academy')
        ) {
          resolve(id);
        } else {
          reject(new Error('not found'));
        }
      }, 2000);
    }
  }

  getRoles(user) {
    return new Promise((resolve, reject) => {
      setTimeout(()=> {
        if (user === 'ellie') {
          onSuccess({ name: 'ellie', role: 'admin' });
        } else {
          onError(new Error('no access'));
        }
      }, 1000);
    })
  }
}

const userStorage = new UserStorage();
const id = prompt('enter your id');
const password = promt('enter ypur password');

userStorage
  .loginUser(id, password)
  .then(userStorage.getRoles)
  .then(user => alert(`Hello ${userWithRole.name}, you have a ${userWithRole.role} role.`)
  .catch(console.log);
```